{"text": "2025-06-30 19:44:17.405 | ERROR    | src.dynel.exception_handling:handle_exception:110 - Exception caught in function_writing_to_log_files\nTraceback (most recent call last):\n\n  File \"<frozen runpy>\", line 198, in _run_module_as_main\n  File \"<frozen runpy>\", line 88, in _run_code\n  File \"C:\\Users\\tyler\\AppData\\Local\\Packages\\PythonSoftwareFoundation.Python.3.11_qbz5n2kfra8p0\\LocalCache\\local-packages\\Python311\\site-packages\\pytest\\__main__.py\", line 9, in <module>\n    raise SystemExit(pytest.console_main())\n                     │      └ <function console_main at 0x0000020C8E5560C0>\n                     └ <module 'pytest' from 'C:\\\\Users\\\\tyler\\\\AppData\\\\Local\\\\Packages\\\\PythonSoftwareFoundation.Python.3.11_qbz5n2kfra8p0\\\\LocalC...\n  File \"C:\\Users\\tyler\\AppData\\Local\\Packages\\PythonSoftwareFoundation.Python.3.11_qbz5n2kfra8p0\\LocalCache\\local-packages\\Python311\\site-packages\\_pytest\\config\\__init__.py\", line 201, in console_main\n    code = main()\n           └ <function main at 0x0000020C8E556020>\n  File \"C:\\Users\\tyler\\AppData\\Local\\Packages\\PythonSoftwareFoundation.Python.3.11_qbz5n2kfra8p0\\LocalCache\\local-packages\\Python311\\site-packages\\_pytest\\config\\__init__.py\", line 175, in main\n    ret: ExitCode | int = config.hook.pytest_cmdline_main(config=config)\n         │                │      │    │                          └ <_pytest.config.Config object at 0x0000020C8E833FD0>\n         │                │      │    └ <HookCaller 'pytest_cmdline_main'>\n         │                │      └ <_pytest.config.compat.PathAwareHookProxy object at 0x0000020C8E83C210>\n         │                └ <_pytest.config.Config object at 0x0000020C8E833FD0>\n         └ <enum 'ExitCode'>\n  File \"C:\\Users\\tyler\\AppData\\Local\\Packages\\PythonSoftwareFoundation.Python.3.11_qbz5n2kfra8p0\\LocalCache\\local-packages\\Python311\\site-packages\\pluggy\\_hooks.py\", line 512, in __call__\n    return self._hookexec(self.name, self._hookimpls.copy(), kwargs, firstresult)\n           │    │         │    │     │    │                  │       └ True\n           │    │         │    │     │    │                  └ {'config': <_pytest.config.Config object at 0x0000020C8E833FD0>}\n           │    │         │    │     │    └ <member '_hookimpls' of 'HookCaller' objects>\n           │    │         │    │     └ <HookCaller 'pytest_cmdline_main'>\n           │    │         │    └ <member 'name' of 'HookCaller' objects>\n           │    │         └ <HookCaller 'pytest_cmdline_main'>\n           │    └ <member '_hookexec' of 'HookCaller' objects>\n           └ <HookCaller 'pytest_cmdline_main'>\n  File \"C:\\Users\\tyler\\AppData\\Local\\Packages\\PythonSoftwareFoundation.Python.3.11_qbz5n2kfra8p0\\LocalCache\\local-packages\\Python311\\site-packages\\pluggy\\_manager.py\", line 120, in _hookexec\n    return self._inner_hookexec(hook_name, methods, kwargs, firstresult)\n           │    │               │          │        │       └ True\n           │    │               │          │        └ {'config': <_pytest.config.Config object at 0x0000020C8E833FD0>}\n           │    │               │          └ [<HookImpl plugin_name='main', plugin=<module '_pytest.main' from 'C:\\\\Users\\\\tyler\\\\AppData\\\\Local\\\\Packages\\\\PythonSoftware...\n           │    │               └ 'pytest_cmdline_main'\n           │    └ <function _multicall at 0x0000020C8E0CB9C0>\n           └ <_pytest.config.PytestPluginManager object at 0x0000020C8DD5E750>\n  File \"C:\\Users\\tyler\\AppData\\Local\\Packages\\PythonSoftwareFoundation.Python.3.11_qbz5n2kfra8p0\\LocalCache\\local-packages\\Python311\\site-packages\\pluggy\\_callers.py\", line 121, in _multicall\n    res = hook_impl.function(*args)\n          │         │         └ [<_pytest.config.Config object at 0x0000020C8E833FD0>]\n          │         └ <member 'function' of 'HookImpl' objects>\n          └ <HookImpl plugin_name='main', plugin=<module '_pytest.main' from 'C:\\\\Users\\\\tyler\\\\AppData\\\\Local\\\\Packages\\\\PythonSoftwareF...\n  File \"C:\\Users\\tyler\\AppData\\Local\\Packages\\PythonSoftwareFoundation.Python.3.11_qbz5n2kfra8p0\\LocalCache\\local-packages\\Python311\\site-packages\\_pytest\\main.py\", line 336, in pytest_cmdline_main\n    return wrap_session(config, _main)\n           │            │       └ <function _main at 0x0000020C8E6100E0>\n           │            └ <_pytest.config.Config object at 0x0000020C8E833FD0>\n           └ <function wrap_session at 0x0000020C8E607F60>\n  File \"C:\\Users\\tyler\\AppData\\Local\\Packages\\PythonSoftwareFoundation.Python.3.11_qbz5n2kfra8p0\\LocalCache\\local-packages\\Python311\\site-packages\\_pytest\\main.py\", line 289, in wrap_session\n    session.exitstatus = doit(config, session) or 0\n    │       │            │    │       └ <Session  exitstatus=<ExitCode.OK: 0> testsfailed=0 testscollected=3>\n    │       │            │    └ <_pytest.config.Config object at 0x0000020C8E833FD0>\n    │       │            └ <function _main at 0x0000020C8E6100E0>\n    │       └ <ExitCode.OK: 0>\n    └ <Session  exitstatus=<ExitCode.OK: 0> testsfailed=0 testscollected=3>\n  File \"C:\\Users\\tyler\\AppData\\Local\\Packages\\PythonSoftwareFoundation.Python.3.11_qbz5n2kfra8p0\\LocalCache\\local-packages\\Python311\\site-packages\\_pytest\\main.py\", line 343, in _main\n    config.hook.pytest_runtestloop(session=session)\n    │      │    │                          └ <Session  exitstatus=<ExitCode.OK: 0> testsfailed=0 testscollected=3>\n    │      │    └ <HookCaller 'pytest_runtestloop'>\n    │      └ <_pytest.config.compat.PathAwareHookProxy object at 0x0000020C8E83C210>\n    └ <_pytest.config.Config object at 0x0000020C8E833FD0>\n  File \"C:\\Users\\tyler\\AppData\\Local\\Packages\\PythonSoftwareFoundation.Python.3.11_qbz5n2kfra8p0\\LocalCache\\local-packages\\Python311\\site-packages\\pluggy\\_hooks.py\", line 512, in __call__\n    return self._hookexec(self.name, self._hookimpls.copy(), kwargs, firstresult)\n           │    │         │    │     │    │                  │       └ True\n           │    │         │    │     │    │                  └ {'session': <Session  exitstatus=<ExitCode.OK: 0> testsfailed=0 testscollected=3>}\n           │    │         │    │     │    └ <member '_hookimpls' of 'HookCaller' objects>\n           │    │         │    │     └ <HookCaller 'pytest_runtestloop'>\n           │    │         │    └ <member 'name' of 'HookCaller' objects>\n           │    │         └ <HookCaller 'pytest_runtestloop'>\n           │    └ <member '_hookexec' of 'HookCaller' objects>\n           └ <HookCaller 'pytest_runtestloop'>\n  File \"C:\\Users\\tyler\\AppData\\Local\\Packages\\PythonSoftwareFoundation.Python.3.11_qbz5n2kfra8p0\\LocalCache\\local-packages\\Python311\\site-packages\\pluggy\\_manager.py\", line 120, in _hookexec\n    return self._inner_hookexec(hook_name, methods, kwargs, firstresult)\n           │    │               │          │        │       └ True\n           │    │               │          │        └ {'session': <Session  exitstatus=<ExitCode.OK: 0> testsfailed=0 testscollected=3>}\n           │    │               │          └ [<HookImpl plugin_name='main', plugin=<module '_pytest.main' from 'C:\\\\Users\\\\tyler\\\\AppData\\\\Local\\\\Packages\\\\PythonSoftware...\n           │    │               └ 'pytest_runtestloop'\n           │    └ <function _multicall at 0x0000020C8E0CB9C0>\n           └ <_pytest.config.PytestPluginManager object at 0x0000020C8DD5E750>\n  File \"C:\\Users\\tyler\\AppData\\Local\\Packages\\PythonSoftwareFoundation.Python.3.11_qbz5n2kfra8p0\\LocalCache\\local-packages\\Python311\\site-packages\\pluggy\\_callers.py\", line 121, in _multicall\n    res = hook_impl.function(*args)\n          │         │         └ [<Session  exitstatus=<ExitCode.OK: 0> testsfailed=0 testscollected=3>]\n          │         └ <member 'function' of 'HookImpl' objects>\n          └ <HookImpl plugin_name='main', plugin=<module '_pytest.main' from 'C:\\\\Users\\\\tyler\\\\AppData\\\\Local\\\\Packages\\\\PythonSoftwareF...\n  File \"C:\\Users\\tyler\\AppData\\Local\\Packages\\PythonSoftwareFoundation.Python.3.11_qbz5n2kfra8p0\\LocalCache\\local-packages\\Python311\\site-packages\\_pytest\\main.py\", line 367, in pytest_runtestloop\n    item.config.hook.pytest_runtest_protocol(item=item, nextitem=nextitem)\n    │    │                                        │              └ None\n    │    │                                        └ <Function test_log_file_output_formats>\n    │    └ <member 'config' of 'Node' objects>\n    └ <Function test_log_file_output_formats>\n  File \"C:\\Users\\tyler\\AppData\\Local\\Packages\\PythonSoftwareFoundation.Python.3.11_qbz5n2kfra8p0\\LocalCache\\local-packages\\Python311\\site-packages\\pluggy\\_hooks.py\", line 512, in __call__\n    return self._hookexec(self.name, self._hookimpls.copy(), kwargs, firstresult)\n           │    │         │    │     │    │                  │       └ True\n           │    │         │    │     │    │                  └ {'item': <Function test_log_file_output_formats>, 'nextitem': None}\n           │    │         │    │     │    └ <member '_hookimpls' of 'HookCaller' objects>\n           │    │         │    │     └ <HookCaller 'pytest_runtest_protocol'>\n           │    │         │    └ <member 'name' of 'HookCaller' objects>\n           │    │         └ <HookCaller 'pytest_runtest_protocol'>\n           │    └ <member '_hookexec' of 'HookCaller' objects>\n           └ <HookCaller 'pytest_runtest_protocol'>\n  File \"C:\\Users\\tyler\\AppData\\Local\\Packages\\PythonSoftwareFoundation.Python.3.11_qbz5n2kfra8p0\\LocalCache\\local-packages\\Python311\\site-packages\\pluggy\\_manager.py\", line 120, in _hookexec\n    return self._inner_hookexec(hook_name, methods, kwargs, firstresult)\n           │    │               │          │        │       └ True\n           │    │               │          │        └ {'item': <Function test_log_file_output_formats>, 'nextitem': None}\n           │    │               │          └ [<HookImpl plugin_name='runner', plugin=<module '_pytest.runner' from 'C:\\\\Users\\\\tyler\\\\AppData\\\\Local\\\\Packages\\\\PythonSoft...\n           │    │               └ 'pytest_runtest_protocol'\n           │    └ <function _multicall at 0x0000020C8E0CB9C0>\n           └ <_pytest.config.PytestPluginManager object at 0x0000020C8DD5E750>\n  File \"C:\\Users\\tyler\\AppData\\Local\\Packages\\PythonSoftwareFoundation.Python.3.11_qbz5n2kfra8p0\\LocalCache\\local-packages\\Python311\\site-packages\\pluggy\\_callers.py\", line 121, in _multicall\n    res = hook_impl.function(*args)\n          │         │         └ [<Function test_log_file_output_formats>, None]\n          │         └ <member 'function' of 'HookImpl' objects>\n          └ <HookImpl plugin_name='runner', plugin=<module '_pytest.runner' from 'C:\\\\Users\\\\tyler\\\\AppData\\\\Local\\\\Packages\\\\PythonSoftw...\n  File \"C:\\Users\\tyler\\AppData\\Local\\Packages\\PythonSoftwareFoundation.Python.3.11_qbz5n2kfra8p0\\LocalCache\\local-packages\\Python311\\site-packages\\_pytest\\runner.py\", line 117, in pytest_runtest_protocol\n    runtestprotocol(item, nextitem=nextitem)\n    │               │              └ None\n    │               └ <Function test_log_file_output_formats>\n    └ <function runtestprotocol at 0x0000020C8E607240>\n  File \"C:\\Users\\tyler\\AppData\\Local\\Packages\\PythonSoftwareFoundation.Python.3.11_qbz5n2kfra8p0\\LocalCache\\local-packages\\Python311\\site-packages\\_pytest\\runner.py\", line 136, in runtestprotocol\n    reports.append(call_and_report(item, \"call\", log))\n    │       │      │               │             └ True\n    │       │      │               └ <Function test_log_file_output_formats>\n    │       │      └ <function call_and_report at 0x0000020C8E6076A0>\n    │       └ <method 'append' of 'list' objects>\n    └ [<TestReport 'tests/test_logging_utils.py::test_log_file_output_formats' when='setup' outcome='passed'>]\n  File \"C:\\Users\\tyler\\AppData\\Local\\Packages\\PythonSoftwareFoundation.Python.3.11_qbz5n2kfra8p0\\LocalCache\\local-packages\\Python311\\site-packages\\_pytest\\runner.py\", line 245, in call_and_report\n    call = CallInfo.from_call(\n           │        └ <classmethod(<function CallInfo.from_call at 0x0000020C8E6079C0>)>\n           └ <class '_pytest.runner.CallInfo'>\n  File \"C:\\Users\\tyler\\AppData\\Local\\Packages\\PythonSoftwareFoundation.Python.3.11_qbz5n2kfra8p0\\LocalCache\\local-packages\\Python311\\site-packages\\_pytest\\runner.py\", line 344, in from_call\n    result: TResult | None = func()\n            │                └ <function call_and_report.<locals>.<lambda> at 0x0000020C911B5760>\n            └ +TResult\n  File \"C:\\Users\\tyler\\AppData\\Local\\Packages\\PythonSoftwareFoundation.Python.3.11_qbz5n2kfra8p0\\LocalCache\\local-packages\\Python311\\site-packages\\_pytest\\runner.py\", line 246, in <lambda>\n    lambda: runtest_hook(item=item, **kwds), when=when, reraise=reraise\n            │                 │       └ {}\n            │                 └ <Function test_log_file_output_formats>\n            └ <HookCaller 'pytest_runtest_call'>\n  File \"C:\\Users\\tyler\\AppData\\Local\\Packages\\PythonSoftwareFoundation.Python.3.11_qbz5n2kfra8p0\\LocalCache\\local-packages\\Python311\\site-packages\\pluggy\\_hooks.py\", line 512, in __call__\n    return self._hookexec(self.name, self._hookimpls.copy(), kwargs, firstresult)\n           │    │         │    │     │    │                  │       └ False\n           │    │         │    │     │    │                  └ {'item': <Function test_log_file_output_formats>}\n           │    │         │    │     │    └ <member '_hookimpls' of 'HookCaller' objects>\n           │    │         │    │     └ <HookCaller 'pytest_runtest_call'>\n           │    │         │    └ <member 'name' of 'HookCaller' objects>\n           │    │         └ <HookCaller 'pytest_runtest_call'>\n           │    └ <member '_hookexec' of 'HookCaller' objects>\n           └ <HookCaller 'pytest_runtest_call'>\n  File \"C:\\Users\\tyler\\AppData\\Local\\Packages\\PythonSoftwareFoundation.Python.3.11_qbz5n2kfra8p0\\LocalCache\\local-packages\\Python311\\site-packages\\pluggy\\_manager.py\", line 120, in _hookexec\n    return self._inner_hookexec(hook_name, methods, kwargs, firstresult)\n           │    │               │          │        │       └ False\n           │    │               │          │        └ {'item': <Function test_log_file_output_formats>}\n           │    │               │          └ [<HookImpl plugin_name='threadexception', plugin=<module '_pytest.threadexception' from 'C:\\\\Users\\\\tyler\\\\AppData\\\\Local\\\\Pa...\n           │    │               └ 'pytest_runtest_call'\n           │    └ <function _multicall at 0x0000020C8E0CB9C0>\n           └ <_pytest.config.PytestPluginManager object at 0x0000020C8DD5E750>\n  File \"C:\\Users\\tyler\\AppData\\Local\\Packages\\PythonSoftwareFoundation.Python.3.11_qbz5n2kfra8p0\\LocalCache\\local-packages\\Python311\\site-packages\\pluggy\\_callers.py\", line 121, in _multicall\n    res = hook_impl.function(*args)\n          │         │         └ [<Function test_log_file_output_formats>]\n          │         └ <member 'function' of 'HookImpl' objects>\n          └ <HookImpl plugin_name='runner', plugin=<module '_pytest.runner' from 'C:\\\\Users\\\\tyler\\\\AppData\\\\Local\\\\Packages\\\\PythonSoftw...\n  File \"C:\\Users\\tyler\\AppData\\Local\\Packages\\PythonSoftwareFoundation.Python.3.11_qbz5n2kfra8p0\\LocalCache\\local-packages\\Python311\\site-packages\\_pytest\\runner.py\", line 178, in pytest_runtest_call\n    item.runtest()\n    │    └ <function Function.runtest at 0x0000020C8E7340E0>\n    └ <Function test_log_file_output_formats>\n  File \"C:\\Users\\tyler\\AppData\\Local\\Packages\\PythonSoftwareFoundation.Python.3.11_qbz5n2kfra8p0\\LocalCache\\local-packages\\Python311\\site-packages\\_pytest\\python.py\", line 1671, in runtest\n    self.ihook.pytest_pyfunc_call(pyfuncitem=self)\n    │    │                                   └ <Function test_log_file_output_formats>\n    │    └ <property object at 0x0000020C8E580C70>\n    └ <Function test_log_file_output_formats>\n  File \"C:\\Users\\tyler\\AppData\\Local\\Packages\\PythonSoftwareFoundation.Python.3.11_qbz5n2kfra8p0\\LocalCache\\local-packages\\Python311\\site-packages\\pluggy\\_hooks.py\", line 512, in __call__\n    return self._hookexec(self.name, self._hookimpls.copy(), kwargs, firstresult)\n           │    │         │    │     │    │                  │       └ True\n           │    │         │    │     │    │                  └ {'pyfuncitem': <Function test_log_file_output_formats>}\n           │    │         │    │     │    └ <member '_hookimpls' of 'HookCaller' objects>\n           │    │         │    │     └ <HookCaller 'pytest_pyfunc_call'>\n           │    │         │    └ <member 'name' of 'HookCaller' objects>\n           │    │         └ <HookCaller 'pytest_pyfunc_call'>\n           │    └ <member '_hookexec' of 'HookCaller' objects>\n           └ <HookCaller 'pytest_pyfunc_call'>\n  File \"C:\\Users\\tyler\\AppData\\Local\\Packages\\PythonSoftwareFoundation.Python.3.11_qbz5n2kfra8p0\\LocalCache\\local-packages\\Python311\\site-packages\\pluggy\\_manager.py\", line 120, in _hookexec\n    return self._inner_hookexec(hook_name, methods, kwargs, firstresult)\n           │    │               │          │        │       └ True\n           │    │               │          │        └ {'pyfuncitem': <Function test_log_file_output_formats>}\n           │    │               │          └ [<HookImpl plugin_name='python', plugin=<module '_pytest.python' from 'C:\\\\Users\\\\tyler\\\\AppData\\\\Local\\\\Packages\\\\PythonSoft...\n           │    │               └ 'pytest_pyfunc_call'\n           │    └ <function _multicall at 0x0000020C8E0CB9C0>\n           └ <_pytest.config.PytestPluginManager object at 0x0000020C8DD5E750>\n  File \"C:\\Users\\tyler\\AppData\\Local\\Packages\\PythonSoftwareFoundation.Python.3.11_qbz5n2kfra8p0\\LocalCache\\local-packages\\Python311\\site-packages\\pluggy\\_callers.py\", line 121, in _multicall\n    res = hook_impl.function(*args)\n          │         │         └ [<Function test_log_file_output_formats>]\n          │         └ <member 'function' of 'HookImpl' objects>\n          └ <HookImpl plugin_name='python', plugin=<module '_pytest.python' from 'C:\\\\Users\\\\tyler\\\\AppData\\\\Local\\\\Packages\\\\PythonSoftw...\n  File \"C:\\Users\\tyler\\AppData\\Local\\Packages\\PythonSoftwareFoundation.Python.3.11_qbz5n2kfra8p0\\LocalCache\\local-packages\\Python311\\site-packages\\_pytest\\python.py\", line 157, in pytest_pyfunc_call\n    result = testfunction(**testargs)\n             │              └ {'tmp_path': WindowsPath('C:/Users/tyler/AppData/Local/Temp/pytest-of-tyler/pytest-2/test_log_file_output_formats0'), 'monkey...\n             └ <function test_log_file_output_formats at 0x0000020C911A3B00>\n\n> File \"C:\\Users\\tyler\\Documents\\devel\\github\\projects\\DynEL\\tests\\test_logging_utils.py\", line 125, in test_log_file_output_formats\n    raise error_to_raise\n          └ IndexError('Test index out of bounds')\n\nIndexError: Test index out of bounds\n", "record": {"elapsed": {"repr": "0:00:00.045085", "seconds": 0.045085}, "exception": {"type": "IndexError", "value": "Test index out of bounds", "traceback": true}, "extra": {"timestamp": "2025-06-30T23:44:17.405033+00:00", "local_vars": "{'alpha': 1, 'beta': 'two'}", "exception": "Test index out of bounds"}, "file": {"name": "exception_handling.py", "path": "C:\\Users\\tyler\\Documents\\devel\\github\\projects\\DynEL\\src\\dynel\\exception_handling.py"}, "function": "handle_exception", "level": {"icon": "❌", "name": "ERROR", "no": 40}, "line": 110, "message": "Exception caught in function_writing_to_log_files", "module": "exception_handling", "name": "src.dynel.exception_handling", "process": {"id": 35212, "name": "MainProcess"}, "thread": {"id": 14444, "name": "MainThread"}, "time": {"repr": "2025-06-30 19:44:17.405033-04:00", "timestamp": 1751327057.405033}}}
